Workbook

Sheet DASHBOARD
A5: SCHOOLS DIVISION OF PARANAQUE CITY
A6: PARANAQUE NATIONAL HIGH SCHOOL - MAIN
A7: SENIOR HIGH SCHOOL PROGRAM
A8: ASSESSMENT PERFORMANCE METRICS (MEAN, MPS, SD)
A9: SY 2025-2026

Sheet ABM
A4: SCHOOLS DIVISION OF PARANAQUE CITY
A5: PARANAQUE NATIONAL HIGH SCHOOL - MAIN
A6: SENIOR HIGH SCHOOL PROGRAM
A7: ASSESSMENT PERFORMANCE METRICS (MEAN, MPS, SD)
A8: SY 2025-2026
A10: ASSESSMENT | B10: 1ST PERIODIC TEST
A12: ABM
A13: GRADE LEVEL | B13: Enrollment based on LIS | E13: Number of Test Takers | H13: % of Test Takers | I13: Total Test Items | J13: Highest Scores | K13: Lowest Scores | L13: MEAN | M13: MPS | N13: SD | O13: TOP 5 ITEMS WITH THE MOST NUMBER OF INCORRECT RESPONSES
B15: Male | C15: Female | D15: Total | E15: Male | F15: Female | G15: Total
O16: Rank 1 | P16: Rank 2 | Q16: Rank 3 | R16: Rank 4 | S16: Rank 5
A17: APPLIED SUBJECTS
A18: Entrepreneurship | B18: ='SHS- CONSO'!B33 -> 769 | C18: ='SHS- CONSO'!C33 -> 891 | D18: ='SHS- CONSO'!D33 -> 1660 | E18: 1661 | F18: 1579 | G18: =sum(E18:F18) -> 3240 | H18: N/A | I18: 40 | J18: 39 | K18: 3 | L18: 28.96 | M18: =IFERROR(((L18/I18)*100)," ") -> 72.4 | N18: 6.21 | O18: 16 | P18: 24 | Q18: 17 | R18: 18 | S18: 28
A19: SPECIALIZED SUBJECTS
A20: Applied Economics | B20: ='SHS- CONSO'!B45 -> 848 | C20: ='SHS- CONSO'!C45 -> 966 | D20: ='SHS- CONSO'!D45 -> 1814 | E20: ='SHS- CONSO'!E45 -> 730 | F20: ='SHS- CONSO'!F45 -> 915 | G20: ='SHS- CONSO'!G45 -> 1645 | H20: ='SHS- CONSO'!I45 -> 40 | I20: ='SHS- CONSO'!J45 -> 36 | J20: ='SHS- CONSO'!K45 -> 10 | K20: ='SHS- CONSO'!L45 -> 23.51 | L20: ='SHS- CONSO'!M45 -> 58.775 | M20: ='SHS- CONSO'!N45 -> 5.53 | N20: ='SHS- CONSO'!O45 -> 40 | O20: ='SHS- CONSO'!P45 -> 30 | ... R20: ='SHS- CONSO'!S45 -> 24
A21: Business Ethics and Social Responsibility | B21: ='SHS- CONSO'!B46 -> 769 | C21: ='SHS- CONSO'!C46 -> 891 | D21: ='SHS- CONSO'!D46 -> 1660 | E21: ='SHS- CONSO'!E46 -> 747 | F21: ='SHS- CONSO'!F46 -> 871 | G21: ='SHS- CONSO'!G46 -> 1618 | H21: ='SHS- CONSO'!I46 -> 40 | I21: ='SHS- CONSO'!J46 -> 40 | J21: ='SHS- CONSO'!K46 -> 9 | K21: ='SHS- CONSO'!L46 -> 27.56 | L21: ='SHS- CONSO'!M46 -> 68.9 | M21: ='SHS- CONSO'!N46 -> 6.57 | N21: ='SHS- CONSO'!O46 -> 11 | O21: ='SHS- CONSO'!P46 -> 2 | ... R21: ='SHS- CONSO'!S46 -> 10
A22: Business Finance | B22: 255 | C22: 412 | D22: =sum(B22:C22) -> 667 | E22: 251 | F22: 402 | G22: =sum(E22:F22) -> 653 | H22: N/A | I22: 40 | J22: 35 | K22: 4 | L22: 18.83 | M22: =IFERROR(((L22/I22)*100)," ") -> 47.075 | N22: 5.51 | O22: 13 | P22: 17 | Q22: 24 | R22: 19 | S22: 23
A23: Business Mathematics | B23: N/A | C23: N/A | D23: =sum(B23:C23) -> 0 | E23: 258 | F23: 396 | G23: =sum(E23:F23) -> 654 | H23: N/A | I23: 40 | J23: 36 | K23: 5 | L23: 18.3 | M23: =IFERROR(((L23/I23)*100)," ") -> 45.75 | N23: 6.7 | O23: 6 | P23: 31 | Q23: 15 | R23: 32 | S23: 3
A24: Fundamentals of Accountancy 1 | B24: ='SHS- CONSO'!B49 | C24: ='SHS- CONSO'!C49 | D24: =sum(B24:C24) -> 0 | G24: =sum(E24:F24) -> 0 | H24: N/A | M24: =IFERROR(((L24/I24)*100)," ")
A25: Fundamentals of Accountancy 2 | B25: N/A | C25: N/A | D25: =sum(B25:C25) -> 0 | E25: 251 | F25: 402 | G25: =sum(E25:F25) -> 653 | H25: N/A | I25: 40 | J25: 35 | K25: 5 | L25: 17.9 | M25: =IFERROR(((L25/I25)*100)," ") -> 44.75 | N25: 5.9 | O25: 12 | P25: 15 | Q25: 39 | R25: 40 | S25: 18
A26: Organization and Management | B26: N/A | C26: N/A | D26: =sum(B26:C26) -> 0 | E26: 260 | F26: 400 | G26: =sum(E26:F26) -> 660 | H26: N/A | I26: 40 | J26: 37 | K26: 5 | L26: 21.87 | M26: =IFERROR(((L26/I26)*100)," ") -> 54.675 | N26: 5.9 | O26: 38 | P26: 9 | Q26: 18 | R26: 4 | S26: 8
A27: Principles of Marketing | B27: ='SHS- CONSO'!B52 | C27: ='SHS- CONSO'!C52 | D27: ='SHS- CONSO'!D52 | E27: ='SHS- CONSO'!E52 | F27: ='SHS- CONSO'!F52 | G27: ='SHS- CONSO'!G52 | H27: ='SHS- CONSO'!I52 | I27: ='SHS- CONSO'!J52 | J27: ='SHS- CONSO'!K52 | K27: ='SHS- CONSO'!L52 | L27: ='SHS- CONSO'!M52 | M27: ='SHS- CONSO'!N52 | N27: ='SHS- CONSO'!O52 | O27: ='SHS- CONSO'!P52 | ... R27: ='SHS- CONSO'!S52
A28: TOTAL | B28: =SUM(B17:B27) -> 2641 | C28: =SUM(C17:C27) -> 3160 | D28: =SUM(D17:D27) -> 5801 | E28: =SUM(E17:E27) -> 4158 | F28: =SUM(F17:F27) -> 4965 | G28: =SUM(G17:G27) -> 9123 | H28: =AVERAGE(H17:H27) -> 40 | I28: =AVERAGE(I17:I27) -> 39.428571 | J28: =IFERROR((AVERAGE(J16:J19,J21:J24,J26:J27)),"") -> 31.2 | K28: =IFERROR((AVERAGE(K16:K19,K21:K24,K26:K27)),"") -> 8.912 | L28: =IFERROR((AVERAGE(L16:L19,L21:L24,L26:L27)),"") -> 31.372 | M28: =IFERROR((AVERAGE(M16:M19,M21:M24,M26:M27)),"") -> 45.294 | N28: =IFERROR((AVERAGE(N16:N19,N21:N24,N26:N27)),"") -> 7.064 | O28: =IFERROR((AVERAGE(O16:O19,O21:O24,O26:O27)),"") -> 15 | P28: =IFERROR((AVERAGE(P16:P19,P21:P24,P26:P27)),"") -> 20.4 | Q28: =IFERROR((AVERAGE(Q16:Q19,Q21:Q24,Q26:Q27)),"") -> 20 | ... S28: =IFERROR((AVERAGE(S16:S19,S21:S24,S26:S27)),"") -> 15.5

Sheet ENG
A4: SCHOOLS DIVISION OF PARANAQUE CITY
A5: PARANAQUE NATIONAL HIGH SCHOOL - MAIN
A6: SENIOR HIGH SCHOOL PROGRAM
A7: ASSESSMENT PERFORMANCE METRICS (MEAN, MPS, SD)
A8: SY 2025-2026
A10: ASSESSMENT | B10: 1ST PERIODIC TEST
A12: ENGLISH
A13: GRADE LEVEL | B13: Enrollment based on LIS | E13: Number of Test Takers | H13: % of Test Takers | I13: Total Test Items | J13: Highest Scores | K13: Lowest Scores | L13: MEAN | M13: MPS | N13: SD | O13: TOP 5 ITEMS WITH THE MOST NUMBER OF INCORRECT RESPONSES
B15: Male | C15: Female | D15: Total | E15: Male | F15: Female | G15: Total
O16: Rank 1 | P16: Rank 2 | Q16: Rank 3 | R16: Rank 4 | S16: Rank 5
A17: CORE SUBJECTS
A18: 21st Century Literature from the Philippines and the World | B18: ='SHS- CONSO'!B17 -> 980 | C18: ='SHS- CONSO'!C17 -> 926 | D18: =sum(B18:C18) -> 1906 | E18: 813 | F18: 801 | G18: =sum(E18:F18) -> 1614 | H18: N/A | I18: 40 | J18: 38 | K18: 11 | L18: 24.5 | M18: =IFERROR(((L18/I18)*100)," ") -> 61.25 | N18: 4.5 | O18: 4 | P18: 11 | Q18: 17 | R18: 33 | S18: 38
A19: Media and Information Literacy | B19: ='SHS- CONSO'!B25 -> 848 | C19: ='SHS- CONSO'!C25 -> 966 | D19: =sum(B19:C19) -> 1814 | E19: 799 | F19: 963 | G19: =sum(E19:F19) -> 1762 | H19: N/A | I19: 40 | J19: 39 | K19: 9 | L19: 26.2 | M19: =IFERROR(((L19/I19)*100)," ") -> 65.5 | N19: 5.4 | O19: 23 | P19: 21 | Q19: 16 | R19: 34 | S19: 15
A20: Oral Communication in Context | B20: ='SHS- CONSO'!B26 -> 721 | C20: ='SHS- CONSO'!C26 -> 621 | D20: =sum(B20:C20) -> 1342 | E20: 726 | F20: 562 | G20: =sum(E20:F20) -> 1288 | H20: N/A | I20: 40 | J20: 40 | K20: 5 | L20: 21.89 | M20: =IFERROR(((L20/I20)*100)," ") -> 54.725 | N20: 6.34 | O20: 22 | P20: 23 | Q20: 16 | R20: 30 | S20: 25
A21: Reading and Writing Skills | B21: ='SHS- CONSO'!B32 -> 769 | C21: ='SHS- CONSO'!C32 -> 891 | D21: =sum(B21:C21) -> 1660 | E21: 755 | F21: 877 | G21: =sum(E21:F21) -> 1632 | H21: N/A | I21: 40 | J21: 38 | K21: 8 | L21: 26.94 | M21: =IFERROR(((L21/I21)*100)," ") -> 67.35 | N21: 8.94 | O21: 34 | P21: 21 | Q21: 23 | R21: 34 | S21: 36
A22: APPLIED SUBJECTS
A23: English for Academic and Professional Purposes | B23: ='SHS- CONSO'!B43 -> 721 | C23: ='SHS- CONSO'!C43 -> 621 | D23: =sum(B23:C23) -> 1342 | E23: 674 | F23: 594 | G23: =sum(E23:F23) -> 1268 | H23: N/A | I23: 40 | J23: 34 | K23: 13 | L23: 23.5 | M23: 58.75 | N23: 3.5 | O23: 36 | P23: 9 | Q23: 6 | R23: 11 | S23: 3
A24: Research Project / Inquiries, Immersion, Investigation | C24: N/A | D24: =sum(B24:C24) -> 0 | G24: =sum(E24:F24) -> 0 | H24: N/A | I24: 40 | M24: =IFERROR(((L24/I24)*100)," ") -> 0
A25: Practical Research 1 | B25: ='SHS- CONSO'!B46 -> 769 | C25: ='SHS- CONSO'!C46 -> 891 | D25: =sum(B25:C25) -> 1660 | E25: 747 | F25: 871 | G25: =sum(E25:F25) -> 1618 | H25: N/A | I25: 40 | J25: 40 | K25: 9 | L25: 27.56 | M25: =IFERROR(((L25/I25)*100)," ") -> 68.9 | N25: 6.57 | O25: 11 | P25: 2 | Q25: 21 | R25: 26 | S25: 10
A26: Practical Research 2 | B26: ='SHS- CONSO'!B47 -> 1709 | C26: ='SHS- CONSO'!C47 -> 1684 | D26: =sum(B26:C26) -> 3393 | E26: 1253 | F26: 1279 | G26: =sum(E26:F26) -> 2532 | H26: N/A | I26: ='SHS- CONSO'!I47 -> 40 | J26: 40 | K26: 10 | L26: 25 | M26: =IFERROR(((L26/I26)*100)," ") -> 62.5 | N26: 5 | O26: 9 | P26: 13 | Q26: 39 | R26: 28 | S26: 29
A27: SPECIALIZED SUBJECTS
A28: Creative Non-Fiction | B28: ='SHS- CONSO'!B67 -> 140 | C28: ='SHS- CONSO'!C67 -> 183 | D28: =sum(B28:C28) -> 323 | E28: 134 | F28: 175 | G28: =sum(E28:F28) -> 309 | H28: N/A | I28: 40 | J28: 38 | K28: 7 | L28: 21.5 | M28: =IFERROR(((L28/I28)*100)," ") -> 53.75 | N28: 6.33 | O28: 40 | P28: 11 | Q28: 13 | R28: 35 | S28: 4
A29: Creative Writing | B29: ='SHS- CONSO'!B68 -> 0 | C29: ='SHS- CONSO'!C68 -> 0 | D29: =sum(B29:C29) -> 0 | E29: N/A | F29: N/A | G29: =sum(E29:F29) -> 0 | H29: N/A | I29: 40 | J29: N/A | K29: N/A | L29: N/A | M29: N/A | N29: N/A | O29: N/A | P29: N/A | Q29: N/A | R29: N/A | S29: N/A
A30: TOTAL | B30: =SUM(B18:B21,B23:B26,B28:B29) -> 6657 | C30: =SUM(C18:C21,C23:C26,C28:C29) -> 6783 | D30: =SUM(D18:D21,D23:D26,D28:D29) -> 13440 | E30: =SUM(E18:E21,E23:E26,E28:E29) -> 5901 | F30: =SUM(F18:F21,F23:F26,F28:F29) -> 6122 | G30: =SUM(G18:G21,G23:G26,G28:G29) -> 12023 | I30: =AVERAGE(I18:I21,I23:I26,I28:I29) -> 40 | J30: =IFERROR((AVERAGE(J18:J21,J23:J26,J28:J29)),"") -> 38.375 | K30: =IFERROR((AVERAGE(K18:K21,K23:K26,K28:K29)),"") -> 9 | L30: =IFERROR((AVERAGE(L18:L21,L23:L26,L28:L29)),"") -> 24.63625 | M30: =IFERROR((AVERAGE(M18:M21,M23:M26,M28:M29)),"") -> 54.747222 | N30: =IFERROR((AVERAGE(N18:N21,N23:N26,N28:N29)),"") -> 5.8225 | O30: =IFERROR((AVERAGE(O18:O21,O23:O26,O28:O29)),"") -> 22.375 | P30: =IFERROR((AVERAGE(P18:P21,P23:P26,P28:P29)),"") -> 13.875 | Q30: =IFERROR((AVERAGE(Q18:Q21,Q23:Q26,Q28:Q29)),"") -> 18.875 | ... S30: =IFERROR((AVERAGE(S18:S21,S23:S26,S28:S29)),"") -> 20

Sheet SHS-NUMBER
A1: SCHOOLS DIVISION OF PARANAQUE CITY
A2: PARANAQUE NATIONAL HIGH SCHOOL - MAIN
A3: ='SHS- CONSO'!A6 -> SENIOR HIGH SCHOOL PROGRAM
A4: CONSOLIDATED SUMMARY OF TEST RESULTS ANALYSIS (MEAN, MPS, SD)
A5: SY 2025-2026
A7: ASSESSMENT | B7: PRE-TEST
A10: CORE SUBJECTS
A11: GRADE LEVEL | B11: GRADE 11 | E11: GRADE 12 | H11: TOTAL
B13: Male | C13: Female | D13: Total | E13: Male | F13: Female | G13: Total | H13: Male | I13: Female | J13: Total
A15: 21st Century Literature from the Philippines and the World | B15: =IFERROR(__xludf.DUMMYFUNCTION("IMPORTRANGE(""11ewoQtgLmWCB9shkVV_BqAkWEyjRLk7XsWTW28bbLO8"",""REPORT!C13:D30"")"),"#REF!") -> #REF! | D15: =SUM(B15:C15) -> #REF! | E15: =IFERROR(__xludf.DUMMYFUNCTION("IMPORTRANGE(""1GpwZlqt_Nsmb_m6kXxize-IyRR4CJ7AqOwKhThkw23M"",""REPORT!C13:D30"")"),"#REF!") -> #REF! | G15: =SUM(E15:F15) -> #REF! | H15: =SUM(B15,E15) -> #REF! | I15: =SUM(C15,F15) -> 0 | J15: =SUM(H15:I15) -> #REF!
A16: Contemporary Philippine Arts from the Region | D16: =SUM(B16:C16) -> 0 | G16: =SUM(E16:F16) -> 0 | H16: =SUM(B16,E16) -> 0 | I16: =SUM(C16,F16) -> 0 | J16: =SUM(H16:I16) -> 0
A17: Disaster RIsk Reduction and Management | D17: =SUM(B17:C17) -> 0 | G17: =SUM(E17:F17) -> 0 | H17: =SUM(B17,E17) -> 0 | I17: =SUM(C17,F17) -> 0 | J17: =SUM(H17:I17) -> 0
A18: Earth Science | D18: =SUM(B18:C18) -> 0 | G18: =SUM(E18:F18) -> 0 | H18: =SUM(B18,E18) -> 0 | I18: =SUM(C18,F18) -> 0 | J18: =SUM(H18:I18) -> 0
A19: Earth and Life Science | D19: =SUM(B19:C19) -> 0 | G19: =SUM(E19:F19) -> 0 | H19: =SUM(B19,E19) -> 0 | I19: =SUM(C19,F19) -> 0 | J19: =SUM(H19:I19) -> 0
A20: General Mathematics | D20: =SUM(B20:C20) -> 0 | G20: =SUM(E20:F20) -> 0 | H20: =SUM(B20,E20) -> 0 | I20: =SUM(C20,F20) -> 0 | J20: =SUM(H20:I20) -> 0
A21: Introduction to the Philosophy of the Human Person | D21: =SUM(B21:C21) -> 0 | G21: =SUM(E21:F21) -> 0 | H21: =SUM(B21,E21) -> 0 | I21: =SUM(C21,F21) -> 0 | J21: =SUM(H21:I21) -> 0
A22: Komunikasyon at Pananaliksik sa Wika at Kulturang Pilipino | D22: =SUM(B22:C22) -> 0 | G22: =SUM(E22:F22) -> 0 | H22: =SUM(B22,E22) -> 0 | I22: =SUM(C22,F22) -> 0 | J22: =SUM(H22:I22) -> 0
A23: Media and Information Literacy | D23: =SUM(B23:C23) -> 0 | G23: =SUM(E23:F23) -> 0 | H23: =SUM(B23,E23) -> 0 | I23: =SUM(C23,F23) -> 0 | J23: =SUM(H23:I23) -> 0
A24: Oral Communication in Context | D24: =SUM(B24:C24) -> 0 | G24: =SUM(E24:F24) -> 0 | H24: =SUM(B24,E24) -> 0 | I24: =SUM(C24,F24) -> 0 | J24: =SUM(H24:I24) -> 0
A25: Pagbasa at Pagsusuri ng Iba't-ibang Teksto Tungo sa Pananaliksik | D25: =SUM(B25:C25) -> 0 | G25: =SUM(E25:F25) -> 0 | H25: =SUM(B25,E25) -> 0 | I25: =SUM(C25,F25) -> 0 | J25: =SUM(H25:I25) -> 0
A26: Personal Development | D26: =SUM(B26:C26) -> 0 | G26: =SUM(E26:F26) -> 0 | H26: =SUM(B26,E26) -> 0 | I26: =SUM(C26,F26) -> 0 | J26: =SUM(H26:I26) -> 0
A27: Physical Education and Health 1 and 2 | D27: =SUM(B27:C27) -> 0 | G27: =SUM(E27:F27) -> 0 | H27: =SUM(B27,E27) -> 0 | I27: =SUM(C27,F27) -> 0 | J27: =SUM(H27:I27) -> 0
... A32: Understanding Culture Society and Politics | D32: =SUM(B32:C32) -> 0 | G32: =SUM(E32:F32) -> 0 | H32: =SUM(B32,E32) -> 0 | I32: =SUM(C32,F32) -> 0 | J32: =SUM(H32:I32) -> 0
A33: TOTAL | B33: =SUM(B15:B32) -> #REF! | C33: =SUM(C15:C32) -> 0 | D33: =SUM(D15:D32) -> #REF! | E33: =SUM(E15:E32) -> #REF! | F33: =SUM(F15:F32) -> 0 | G33: =SUM(G15:G32) -> #REF! | H33: =SUM(H15:H32) -> #REF! | I33: =SUM(I15:I32) -> 0 | J33: =SUM(J15:J32) -> #REF!
A35: APPLIED SUBJECTS
A36: GRADE LEVEL | B36: GRADE 11 | E36: GRADE 12 | H36: TOTAL
B38: Male | C38: Female | D38: Total | E38: Male | F38: Female | G38: Total | H38: Male | I38: Female | J38: Total
A40: Empowerment Technologies: ICT for Professional Track | B40: =IFERROR(__xludf.DUMMYFUNCTION("IMPORTRANGE(""11ewoQtgLmWCB9shkVV_BqAkWEyjRLk7XsWTW28bbLO8"",""REPORT!C38:D44"")"),"#REF!") -> #REF! | D40: =SUM(B40:C40) -> #REF! | E40: =IFERROR(__xludf.DUMMYFUNCTION("IMPORTRANGE(""1GpwZlqt_Nsmb_m6kXxize-IyRR4CJ7AqOwKhThkw23M"",""REPORT!C38:D44"")"),"#REF!") -> #REF! | G40: =SUM(E40:F40) -> #REF! | H40: =SUM(B40,E40) -> #REF! | I40: =SUM(C40,F40) -> 0 | J40: =SUM(H40:I40) -> #REF!
A41: English for Academic and Professional Purposes | D41: =SUM(B41:C41) -> 0 | G41: =SUM(E41:F41) -> 0 | H41: =SUM(B41,E41) -> 0 | I41: =SUM(C41,F41) -> 0 | J41: =SUM(H41:I41) -> 0
A42: Entrepreneurship | D42: =SUM(B42:C42) -> 0 | G42: =SUM(E42:F42) -> 0 | H42: =SUM(B42,E42) -> 0 | I42: =SUM(C42,F42) -> 0 | J42: =SUM(H42:I42) -> 0
A43: Pagsulat sa Filipino sa Piling Larangan | D43: =SUM(B43:C43) -> 0 | G43: =SUM(E43:F43) -> 0 | H43: =SUM(B43,E43) -> 0 | I43: =SUM(C43,F43) -> 0 | J43: =SUM(H43:I43) -> 0
A44: Practical Research 1 | D44: =SUM(B44:C44) -> 0 | G44: =SUM(E44:F44) -> 0 | H44: =SUM(B44,E44) -> 0 | I44: =SUM(C44,F44) -> 0 | J44: =SUM(H44:I44) -> 0
A45: Practical Research 2 | D45: =SUM(B45:C45) -> 0 | G45: =SUM(E45:F45) -> 0 | H45: =SUM(B45,E45) -> 0 | I45: =SUM(C45,F45) -> 0 | J45: =SUM(H45:I45) -> 0
A46: Research Project / Inquiries, Immersion, Investigation | D46: =SUM(B46:C46) -> 0 | G46: =SUM(E46:F46) -> 0 | H46: =SUM(B46,E46) -> 0 | I46: =SUM(C46,F46) -> 0 | J46: =SUM(H46:I46) -> 0
A47: TOTAL | B47: =SUM(B40:B46) -> #REF! | C47: =SUM(C40:C46) -> 0 | D47: =SUM(D40:D46) -> #REF! | E47: =SUM(E40:E46) -> #REF! | F47: =SUM(F40:F46) -> 0 | G47: =SUM(G40:G46) -> #REF! | H47: =SUM(H40:H46) -> #REF! | I47: =SUM(I40:I46) -> 0 | J47: =SUM(J40:J46) -> #REF!
A49: SPECIALIZED SUBJECTS
A50: GRADE LEVEL | B50: GRADE 11 | E50: GRADE 12 | H50: TOTAL
B52: Male | C52: Female | D52: Total | E52: Male | F52: Female | G52: Total | H52: Male | I52: Female | J52: Total
A54: ABM
A55: Applied Economics | B55: =IFERROR(__xludf.DUMMYFUNCTION("IMPORTRANGE(""11ewoQtgLmWCB9shkVV_BqAkWEyjRLk7XsWTW28bbLO8"",""REPORT!C54:D61"")"),"#REF!") -> #REF! | D55: =SUM(B55:C55) -> #REF! | E55: =IFERROR(__xludf.DUMMYFUNCTION("IMPORTRANGE(""1GpwZlqt_Nsmb_m6kXxize-IyRR4CJ7AqOwKhThkw23M"",""REPORT!C54:D61"")"),"#REF!") -> #REF! | G55: =SUM(E55:F55) -> #REF! | H55: =SUM(B55,E55) -> #REF! | I55: =SUM(C55,F55) -> 0 | J55: =SUM(H55:I55) -> #REF!
...

Sheet ESP
A4: SCHOOLS DIVISION OF PARANAQUE CITY
A5: PARANAQUE NATIONAL HIGH SCHOOL - MAIN
A6: SENIOR HIGH SCHOOL PROGRAM
A7: ASSESSMENT PERFORMANCE METRICS (MEAN, MPS, SD)
A8: SY 2025-2026
A10: ASSESSMENT | B10: 1ST PERIODIC TEST
A12: EDUKASYON SA PAGPAPAKATAO
A13: GRADE LEVEL | B13: Enrollment based on LIS | E13: Number of Test Takers | H13: % of Test Takers | I13: Total Test Items | J13: Highest Scores | K13: Lowest Scores | L13: MEAN | M13: MPS | N13: SD | O13: TOP 5 ITEMS WITH THE MOST NUMBER OF INCORRECT RESPONSES
B15: Male | C15: Female | D15: Total | E15: Male | F15: Female | G15: Total
O16: Rank 1 | P16: Rank 2 | Q16: Rank 3 | R16: Rank 4 | S16: Rank 5
A17: CORE SUBJECTS
A18: Personal Development | B18: ='SHS- CONSO'!B28 -> 769 | C18: ='SHS- CONSO'!C28 -> 891 | D18: =sum(B18:C18) -> 1660 | E18: 762 | F18: 887 | G18: =sum(E18:F18) -> 1649 | H18: N/A | I18: 40 | J18: 38 | K18: 5 | L18: 29.04 | M18: =IFERROR(((L18/I18)*100)," ") -> 72.6 | N18: 4.85 | O18: 7 | P18: 8 | Q18: 38 | R18: 9 | S18: 40
A19: TOTAL | B19: =B18 -> 769 | C19: =C18 -> 891 | D19: =D18 -> 1660 | E19: =E18 -> 762 | F19: =F18 -> 887 | G19: =G18 -> 1649 | I19: =I18 -> 40 | J19: =J18 -> 38 | K19: =K18 -> 5 | L19: =L18 -> 29.04 | M19: =M18 -> 72.6 | N19: =N18 -> 4.85 | Q19: ='SHS- CONSO'!$Q$35 | R19: ='SHS- CONSO'!$R$35 | S19: ='SHS- CONSO'!$S$35

Sheet FIL
A4: SCHOOLS DIVISION OF PARANAQUE CITY
A5: PARANAQUE NATIONAL HIGH SCHOOL - MAIN
A6: SENIOR HIGH SCHOOL PROGRAM
A7: ASSESSMENT PERFORMANCE METRICS (MEAN, MPS, SD)
A8: SY 2025-2026
A10: ASSESSMENT | B10: 1ST PERIODIC TEST
A12: FILIPINO
A13: GRADE LEVEL | B13: Enrollment based on LIS | E13: Number of Test Takers | H13: % of Test Takers | I13: Total Test Items | J13: Highest Scores | K13: Lowest Scores | L13: MEAN | M13: MPS | N13: SD | O13: TOP 5 ITEMS WITH THE MOST NUMBER OF INCORRECT RESPONSES
B15: Male | C15: Female | D15: Total | E15: Male | F15: Female | G15: Total
O16: Rank 1 | P16: Rank 2 | Q16: Rank 3 | R16: Rank 4 | S16: Rank 5
A17: CORE SUBJECTS
A18: Komunikasyon at Pananaliksik sa Wika at Kulturang Pilipino | B18: ='SHS- CONSO'!B24 -> 721 | C18: ='SHS- CONSO'!C24 -> 621 | D18: =sum(B18:C18) -> 1342 | E18: 671 | F18: 547 | G18: =sum(E18:F18) -> 1218 | H18: N/A | I18: 40 | J18: 38 | K18: 6 | L18: 24.72 | M18: =IFERROR(((L18/I18)*100)," ") -> 61.8 | N18: 4.8 | O18: 17 | P18: 15 | Q18: 29 | R18: 22 | S18: 14
A19: Pagbasa at Pagsusuri ng Iba't-ibang Teksto Tungo sa Pananaliksik | B19: ='SHS- CONSO'!B27 -> 769 | C19: ='SHS- CONSO'!C27 -> 891 | D19: =sum(B19:C19) -> 1660 | E19: 768 | F19: 882 | G19: =sum(E19:F19) -> 1650 | H19: N/A | I19: 40 | J19: 40 | K19: 8 | L19: 24.43 | M19: =IFERROR(((L19/I19)*100)," ") -> 61.075 | N19: 4.91 | O19: 27 | P19: 28 | Q19: 4 | R19: 25 | S19: 6
A20: APPLIED SUBJECTS
A21: Pagsulat sa Filipino sa Piling Larangan | B21: ='SHS- CONSO'!B45 -> 848 | C21: ='SHS- CONSO'!C45 -> 966 | D21: =sum(B21:C21) -> 1814 | E21: 730 | F21: 915 | G21: =sum(E21:F21) -> 1645 | H21: N/A | I21: 40 | J21: 36 | K21: 10 | L21: 23.51 | M21: =IFERROR(((L21/I21)*100)," ") -> 58.775 | N21: 5.53 | O21: 40 | P21: 30 | Q21: 26 | R21: 22 | S21: 24
A22: TOTAL | B22: =SUM(B21,B19,B18) -> 2338 | C22: =SUM(C21,C19,C18) -> 2478 | D22: =SUM(D21,D19,D18) -> 4816 | E22: =SUM(E21,E19,E18) -> 2169 | F22: =SUM(F21,F19,F18) -> 2344 | G22: =SUM(G21,G19,G18) -> 4513 | I22: =AVERAGE(I18:I19,I21) -> 40 | J22: =IFERROR((AVERAGE(J10:J13,J15:J18,J20:J21)),"") -> 37 | K22: =IFERROR((AVERAGE(K10:K13,K15:K18,K20:K21)),"") -> 8 | L22: =IFERROR((AVERAGE(L10:L13,L15:L18,L20:L21)),"") -> 24.115 | M22: =IFERROR((AVERAGE(M10:M13,M15:M18,M20:M21)),"") -> 60.2875 | N22: =IFERROR((AVERAGE(N10:N13,N15:N18,N20:N21)),"") -> 5.165 | O22: =IFERROR((AVERAGE(O10:O13,O15:O18,O20:O21)),"") -> 28.5 | P22: =IFERROR((AVERAGE(P10:P13,P15:P18,P20:P21)),"") -> 22.5 | Q22: =IFERROR((AVERAGE(Q10:Q13,Q15:Q18,Q20:Q21)),"") -> 27.5 | ... S22: =IFERROR((AVERAGE(S10:S13,S15:S18,S20:S21)),"") -> 19

Sheet HumSS
A1: B
A4: SCHOOLS DIVISION OF PARANAQUE CITY
A5: PARANAQUE NATIONAL HIGH SCHOOL - MAIN
A6: SENIOR HIGH SCHOOL PROGRAM
A7: ASSESSMENT PERFORMANCE METRICS (MEAN, MPS, SD)
A8: SY 2025-2026
A10: ASSESSMENT | B10: 1ST PERIODIC TEST
A12: HUMSS
A13: GRADE LEVEL | B13: Enrollment based on LIS | E13: Number of Test Takers | H13: % of Test Takers | I13: Total Test Items | J13: Highest Scores | K13: Lowest Scores | L13: MEAN | M13: MPS | N13: SD | O13: TOP 5 ITEMS WITH THE MOST NUMBER OF INCORRECT RESPONSES
B15: Male | C15: Female | D15: Total | E15: Male | F15: Female | G15: Total
O16: Rank 1 | P16: Rank 2 | Q16: Rank 3 | R16: Rank 4 | S16: Rank 5
A17: CORE SUBJECTS
A18: Contemporary Philippine Arts from the Region | B18: ='SHS- CONSO'!B18 -> 861 | C18: ='SHS- CONSO'!C18 -> 718 | D18: =SUM(B18:C18) -> 1579 | E18: 795 | F18: 651 | G18: =SUM(E18:F18) -> 1446 | H18: N/A | I18: 40 | J18: 40 | K18: 8 | L18: 20.16 | M18: =IFERROR(((L18/I18)*100)," ") -> 50.4 | N18: 20.03 | O18: 39 | P18: 13 | Q18: 2 | R18: 3 | S18: 23
A19: Introduction to the Philosophy of the Human Person | B19: ='SHS- CONSO'!B23 -> 848 | C19: ='SHS- CONSO'!C23 -> 966 | D19: =SUM(B19:C19) -> 1814 | E19: 825 | F19: 950 | G19: =SUM(E19:F19) -> 1775 | H19: N/A | I19: 40 | J19: 40 | K19: 7 | L19: 27.71 | M19: =IFERROR(((L19/I19)*100)," ") -> 69.275 | N19: 6.85 | O19: 34 | P19: 28 | Q19: 19 | R19: 35 | S19: 36
A20: Understanding Culture Society and Politics | B20: ='SHS- CONSO'!B34 -> 721 | C20: ='SHS- CONSO'!C34 -> 621 | D20: =SUM(B20:C20) -> 1342 | E20: 712 | F20: 578 | G20: =SUM(E20:F20) -> 1290 | H20: N/A | I20: 40 | J20: 37 | K20: 5 | L20: 16.47 | M20: =IFERROR(((L20/I20)*100)," ") -> 41.175 | N20: 4.23 | O20: 8 | P20: 19 | Q20: 33 | R20: 4 | S20: 21
A21: SPECIALIZED SUBJECTS
A22: Community Engagement, Solidarity and Citizenship | B22: ='SHS- CONSO'!B66 -> N/A | C22: ='SHS- CONSO'!C66 -> N/A | D22: =SUM(B22:C22) -> 0 | G22: =SUM(E22:F22) -> 0 | H22: N/A | I22: 40 | J22: ='SHS- CONSO'!J66 | K22: ='SHS- CONSO'!K66 | L22: ='SHS- CONSO'!L66 | M22: ='SHS- CONSO'!M66 | N22: ='SHS- CONSO'!N66 | O22: ='SHS- CONSO'!O66 | P22: ='SHS- CONSO'!P66 | Q22: ='SHS- CONSO'!Q66 | ... S22: ='SHS- CONSO'!S66
A23: Disciplines and Ideas in Applied Social Sciences | B23: 377 | C23: 479 | D23: =SUM(B23:C23) -> 856 | E23: 375 | F23: 455 | G23: =SUM(E23:F23) -> 830 | H23: N/A | I23: 40 | J23: 33 | K23: 11 | L23: 19 | M23: =IFERROR(((L23/I23)*100)," ") -> 47.5 | N23: 6.3 | O23: 7 | P23: 8 | Q23: 33 | R23: 34 | S23: 23
A24: Disciplines and Ideas in Social Sciences | B24: ='SHS- CONSO'!B70 -> 88 | C24: ='SHS- CONSO'!C70 -> 135 | D24: =SUM(B24:C24) -> 223 | E24: 87 | F24: 130 | G24: =SUM(E24:F24) -> 217 | H24: N/A | I24: 40 | J24: 37 | K24: 6 | L24: 20.35 | M24: =IFERROR(((L24/I24)*100)," ") -> 50.875 | N24: 6.5 | O24: 33 | P24: 35 | Q24: 20 | R24: 37 | S24: 7
A25: Introduction to World Religions and Beliefs System | B25: ='SHS- CONSO'!B71 -> 171 | C25: ='SHS- CONSO'!C71 -> 256 | D25: =SUM(B25:C25) -> 427 | E25: 168 | F25: 253 | G25: =SUM(E25:F25) -> 421 | H25: N/A | I25: 40 | J25: 34 | K25: 8 | L25: 21 | M25: =IFERROR(((L25/I25)*100)," ") -> 52.5 | N25: 6.5 | O25: 14 | P25: 22 | Q25: 33 | R25: 12 | S25: 9
A26: Philippine Politics and Governance | B26: ='SHS- CONSO'!B72 -> 384 | C26: ='SHS- CONSO'!C72 -> 481 | D26: =SUM(B26:C26) -> 865 | E26: 360 | F26: 464 | G26: =SUM(E26:F26) -> 824 | H26: N/A | I26: 40 | J26: 38 | K26: 4 | L26: 18 | M26: =IFERROR(((L26/I26)*100)," ") -> 45 | N26: 6.7 | O26: 14 | P26: 20 | Q26: 23 | R26: 35 | S26: 4
A27: Trends, Network and Critical Thinking | B27: ='SHS- CONSO'!B73 -> N/A | C27: ='SHS- CONSO'!C73 -> N/A | D27: =SUM(B27:C27) -> 0 | G27: =SUM(E27:F27) -> 0 | I27: 40 | J27: ='SHS- CONSO'!J73 | K27: ='SHS- CONSO'!K73 | L27: ='SHS- CONSO'!L73 | M27: ='SHS- CONSO'!M73 | N27: ='SHS- CONSO'!N73 | O27: ='SHS- CONSO'!O73 | P27: ='SHS- CONSO'!P73 | Q27: ='SHS- CONSO'!Q73 | ... S27: ='SHS- CONSO'!S73
A28: TOTAL | B28: =SUM(B18:B27) -> 3450 | C28: =SUM(C18:C27) -> 3656 | D28: =SUM(D18:D27) -> 7106 | E28: =SUM(E18:E27) -> 3322 | F28: =SUM(F18:F27) -> 3481 | G28: =SUM(G18:G27) -> 6803 | I28: =AVERAGE(I18:I27) -> 40 | J28: =IFERROR((AVERAGE(J16:J19,J21:J24,J26:J27)),"") -> 37.6 | K28: =IFERROR((AVERAGE(K16:K19,K21:K24,K26:K27)),"") -> 7.2 | L28: =IFERROR((AVERAGE(L16:L19,L21:L24,L26:L27)),"") -> 21.044 | M28: =IFERROR((AVERAGE(M16:M19,M21:M24,M26:M27)),"") -> 52.61 | N28: =IFERROR((AVERAGE(N16:N19,N21:N24,N26:N27)),"") -> 9.276 | O28: =IFERROR((AVERAGE(O16:O19,O21:O24,O26:O27)),"") -> 25.4 | P28: =IFERROR((AVERAGE(P16:P19,P21:P24,P26:P27)),"") -> 20.8 | Q28: =IFERROR((AVERAGE(Q16:Q19,Q21:Q24,Q26:Q27)),"") -> 19.4 | ... S28: =IFERROR((AVERAGE(S16:S19,S21:S24,S26:S27)),"") -> 18.6

Sheet MATH
A4: SCHOOLS DIVISION OF PARANAQUE CITY
A5: PARANAQUE NATIONAL HIGH SCHOOL - MAIN
A6: SENIOR HIGH SCHOOL PROGRAM
A7: ASSESSMENT PERFORMANCE METRICS (MEAN, MPS, SD)
A8: SY 2025-2026
A10: ASSESSMENT | B10: 1ST PERIODIC TEST
A12: MATH
A13: GRADE LEVEL | B13: Enrollment based on LIS | E13: Number of Test Takers | H13: % of Test Takers | I13: Total Test Items | J13: Highest Scores | K13: Lowest Scores | L13: MEAN | M13: MPS | N13: SD | O13: TOP 5 ITEMS WITH THE MOST NUMBER OF INCORRECT RESPONSES
B15: Male | C15: Female | D15: Total | E15: Male | F15: Female | G15: Total
O16: Rank 1 | P16: Rank 2 | Q16: Rank 3 | R16: Rank 4 | S16: Rank 5
A17: CORE SUBJECTS
A18: General Mathematics | B18: ='SHS- CONSO'!B22 -> 721 | C18: ='SHS- CONSO'!C22 -> 621 | D18: =SUM(B18:C18) -> 1342 | E18: 689 | F18: 613 | G18: =SUM(E18:F18) -> 1302 | H18: N/A | I18: 40 | J18: 31 | K18: 1 | L18: 14.23 | M18: =IFERROR(((L18/I18)*100)," ") -> 35.575 | N18: 4.26 | O18: 24 | P18: 8 | Q18: 26 | R18: 13 | S18: 30
A19: Statistics and Probability | B19: ='SHS- CONSO'!B33 -> 769 | C19: ='SHS- CONSO'!C33 -> 891 | D19: =SUM(B19:C19) -> 1660 | E19: 767 | F19: 888 | G19: =SUM(E19:F19) -> 1655 | H19: N/A | I19: 40 | J19: 38 | K19: 5 | L19: 19.31 | M19: =IFERROR(((L19/I19)*100)," ") -> 48.275 | N19: 5.25 | O19: 12 | P19: 2 | Q19: 39 | R19: 22 | S19: 8
A20: SPECIALIZED SUBJECTS
A21: Basic Calculus | B21: ='SHS- CONSO'!B76 -> N/A | C21: ='SHS- CONSO'!C76 -> N/A | D21: =SUM(B21:C21) -> 0 | G21: =SUM(E21:F21) -> 0 | I21: ='SHS- CONSO'!I76 -> 40
A22: Pre-Calculus | B22: ='SHS- CONSO'!B83 -> 256 | C22: ='SHS- CONSO'!C83 -> 246 | D22: =SUM(B22:C22) -> 502 | E22: 256 | F22: 241 | G22: =SUM(E22:F22) -> 497 | H22: N/A | I22: 40 | J22: 32 | K22: 2 | L22: 19.13 | M22: =IFERROR(((L22/I22)*100)," ") -> 47.825 | N22: 4.83 | O22: 16 | P22: 17 | Q22: 19 | R22: 33 | S22: 36
A23: TOTAL | B23: =SUM(B18:B22) -> 1746 | C23: =SUM(C18:C22) -> 1758 | D23: =SUM(D18:D22) -> 3504 | E23: =SUM(E18:E22) -> 1712 | F23: =SUM(F18:F22) -> 1742 | G23: =SUM(G18:G22) -> 3454 | I23: =AVERAGE(I18:I22) -> 40 | J23: =IFERROR((AVERAGE(J20,#REF!,J21:J22)),"") | K23: =IFERROR((AVERAGE(K20,#REF!,K21:K22)),"") | L23: =IFERROR((AVERAGE(L20,#REF!,L21:L22)),"") | M23: =IFERROR((AVERAGE(M20,#REF!,M21:M22)),"") | N23: =IFERROR((AVERAGE(N20,#REF!,N21:N22)),"") | O23: =IFERROR((AVERAGE(O20,#REF!,O21:O22)),"") | P23: =IFERROR((AVERAGE(P20,#REF!,P21:P22)),"") | Q23: =IFERROR((AVERAGE(Q20,#REF!,Q21:Q22)),"") | ... S23: =IFERROR((AVERAGE(S20,#REF!,S21:S22)),"")

Sheet PE
A4: SCHOOLS DIVISION OF PARANAQUE CITY
A5: PARANAQUE NATIONAL HIGH SCHOOL - MAIN
A6: SENIOR HIGH SCHOOL PROGRAM
A7: ASSESSMENT PERFORMANCE METRICS (MEAN, MPS, SD)
A8: SY 2025-2026
A10: ASSESSMENT | B10: 1ST PERIODIC TEST
A12: PE
A13: GRADE LEVEL | B13: Enrollment based on LIS | E13: Number of Test Takers | H13: % of Test Takers | I13: Total Test Items | J13: Highest Scores | K13: Lowest Scores | L13: MEAN | M13: MPS | N13: SD | O13: TOP 5 ITEMS WITH THE MOST NUMBER OF INCORRECT RESPONSES
B15: Male | C15: Female | D15: Total | E15: Male | F15: Female | G15: Total
O16: Rank 1 | P16: Rank 2 | Q16: Rank 3 | R16: Rank 4 | S16: Rank 5
A17: CORE SUBJECTS
A18: PE 1 and 2 | B18: ='SHS- CONSO'!B29 -> 769 | C18: ='SHS- CONSO'!C29 -> 891 | D18: =SUM(B18:C18) -> 1660 | G18: =SUM(E18:F18) -> 0 | H18: N/A | I18: 40 | M18: =IFERROR(((L18/I18)*100)," ") -> 0
A19: PE 3 and 4 | B19: ='SHS- CONSO'!B30 -> 848 | C19: ='SHS- CONSO'!C30 -> 966 | D19: =SUM(B19:C19) -> 1814 | G19: =SUM(E19:F19) -> 0 | H19: N/A | I19: 40 | M19: =IFERROR(((L19/I19)*100)," ") -> 0
A20: TOTAL | B20: =SUM(B18:B19) -> 1617 | C20: =SUM(C18:C19) -> 1857 | D20: =SUM(D18:D19) -> 3474 | E20: =SUM(E18:E19) -> 0 | F20: =SUM(F18:F19) -> 0 | G20: =SUM(G18:G19) -> 0 | I20: =AVERAGE(I18:I19) -> 40 | J20: =IFERROR((AVERAGE(J8:J11,J13:J16,J18:J19)),"") | K20: =IFERROR((AVERAGE(K8:K11,K13:K16,K18:K19)),"") | L20: =IFERROR((AVERAGE(L8:L11,L13:L16,L18:L19)),"") | M20: =IFERROR((AVERAGE(M8:M11,M13:M16,M18:M19)),"") -> 0 | N20: =IFERROR((AVERAGE(N8:N11,N13:N16,N18:N19)),"") | O20: =IFERROR((AVERAGE(O8:O11,O13:O16,O18:O19)),"") | P20: =IFERROR((AVERAGE(P8:P11,P13:P16,P18:P19)),"") | Q20: =IFERROR((AVERAGE(Q8:Q11,Q13:Q16,Q18:Q19)),"") | ... S20: =IFERROR((AVERAGE(S8:S11,S13:S16,S18:S19)),"")

Sheet SCI
A4: SCHOOLS DIVISION OF PARANAQUE CITY
A5: PARANAQUE NATIONAL HIGH SCHOOL - MAIN
A6: SENIOR HIGH SCHOOL PROGRAM
A7: ASSESSMENT PERFORMANCE METRICS (MEAN, MPS, SD)
A8: SY 2025-2026
A10: ASSESSMENT | B10: 1ST PERIODIC TEST
A12: SCIENCE
A13: GRADE LEVEL | B13: Enrollment based on LIS | E13: Number of Test Takers | H13: % of Test Takers | I13: Total Test Items | J13: Highest Scores | K13: Lowest Scores | L13: MEAN | M13: MPS | N13: SD | O13: TOP 5 ITEMS WITH THE MOST NUMBER OF INCORRECT RESPONSES
B15: Male | C15: Female | D15: Total | E15: Male | F15: Female | G15: Total
O16: Rank 1 | P16: Rank 2 | Q16: Rank 3 | R16: Rank 4 | S16: Rank 5
A17: CORE SUBJECTS
A18: Disaster Risk Reduction Management | B18: ='SHS- CONSO'!B19 -> 169 | C18: ='SHS- CONSO'!C19 -> 181 | D18: =SUM(B18:C18) -> 350 | E18: 170 | F18: 181 | G18: =SUM(E18:F18) -> 351 | H18: N/A | I18: 40 | J18: 40 | K18: 10 | L18: 25.24 | M18: =IFERROR(((L18/I18)*100)," ") -> 63.1 | N18: 4.4 | O18: 29 | P18: 6 | Q18: 13 | R18: 4 | S18: 27
A19: Earth and Life Science | B19: ='SHS- CONSO'!B20 -> 87 | C19: ='SHS- CONSO'!C20 -> 65 | D19: =SUM(B19:C19) -> 152 | E19: 587 | F19: 483 | G19: =SUM(E19:F19) -> 1070 | H19: N/A | I19: 40 | J19: 33 | K19: 6 | L19: 16.32 | M19: =IFERROR(((L19/I19)*100)," ") -> 40.8 | N19: 4.6 | O19: 21 | P19: 13 | Q19: 16 | R19: 31 | S19: 8
A20: Earth Science | B20: ='SHS- CONSO'!B21 -> 634 | C20: ='SHS- CONSO'!C21 -> 556 | D20: =SUM(B20:C20) -> 1190 | E20: 87 | F20: 64 | G20: =SUM(E20:F20) -> 151 | H20: N/A | I20: 40 | J20: 36 | K20: 7 | L20: 24.17 | M20: =IFERROR(((L20/I20)*100)," ") -> 60.425 | N20: 5.02 | O20: 6 | P20: 21 | Q20: 17 | R20: 24 | S20: 7
A21: Physical Science | B21: ='SHS- CONSO'!B31 -> 600 | C21: ='SHS- CONSO'!C31 -> 710 | D21: =SUM(B21:C21) -> 1310 | E21: 600 | F21: 710 | G21: =SUM(E21:F21) -> 1310 | H21: N/A | I21: 40 | J21: 40 | K21: 6 | L21: 20.67 | M21: =IFERROR(((L21/I21)*100)," ") -> 51.675 | N21: 5.77 | O21: 32 | P21: 15 | Q21: 26 | R21: 24 | S21: 25
A22: APPLIED SUBJECTS
A23: Practical Research 2 | B23: ='SHS- CONSO'!B44 -> 1709 | C23: ='SHS- CONSO'!C44 -> 1684 | D23: =SUM(B23:C23) -> 3393 | E23: 332 | F23: 337 | G23: =sum(E23:F23) -> 669 | H23: N/A | I23: 40 | J23: 40 | K23: 7 | L23: 29.08 | M23: =IFERROR(((L23/I23)*100)," ") -> 72.7 | N23: 7.53 | O23: 10 | P23: 8 | Q23: 11 | R23: 5 | S23: 39
A24: SPECIALIZED SUBJECTS
A25: General Biology 1 | B25: ='SHS- CONSO'!B77 -> 332 | C25: ='SHS- CONSO'!C77 -> 337 | D25: =SUM(B25:C25) -> 669 | E25: 326 | F25: 333 | G25: =SUM(E25:F25) -> 659 | H25: N/A | I25: 40 | J25: 40 | K25: 6 | L25: 26.15 | M25: =IFERROR(((L25/I25)*100)," ") -> 65.375 | N25: 7.13 | O25: 15 | P25: 20 | Q25: 19 | R25: 30 | S25: 25
A26: General Biology 2 | B26: ='SHS- CONSO'!B78 -> 0 | C26: ='SHS- CONSO'!C78 -> 0 | D26: =SUM(B26:C26) -> 0 | G26: =SUM(E26:F26) -> 0 | H26: N/A | I26: ='SHS- CONSO'!I78 -> 40 | M26: =IFERROR(((L26/I26)*100)," ") -> 0
A27: General Chemistry 1 | B27: ='SHS- CONSO'!B79 -> 256 | C27: ='SHS- CONSO'!C79 -> 246 | D27: =SUM(B27:C27) -> 502 | E27: 256 | F27: 250 | G27: =SUM(E27:F27) -> 506 | H27: N/A | I27: 40 | J27: 40 | K27: 7 | L27: 19.28 | M27: =IFERROR(((L27/I27)*100)," ") -> 48.2 | N27: 4.87 | O27: 3 | P27: 10 | Q27: 32 | R27: 12 | S27: 35
A28: General Chemistry 2 | B28: ='SHS- CONSO'!B80 -> 0 | C28: ='SHS- CONSO'!C80 -> 0 | D28: =SUM(B28:C28) -> 0 | G28: =SUM(E28:F28) -> 0 | H28: N/A | I28: ='SHS- CONSO'!I80 -> 40 | M28: =IFERROR(((L28/I28)*100)," ") -> 0
A29: General Physics 1 | B29: ='SHS- CONSO'!B81 -> 332 | C29: ='SHS- CONSO'!C81 -> 337 | D29: =SUM(B29:C29) -> 669 | E29: 332 | F29: 337 | G29: =SUM(E29:F29) -> 669 | H29: N/A | I29: 40 | J29: 39 | K29: 7 | L29: 24.9 | M29: =IFERROR(((L29/I29)*100)," ") -> 62.25 | N29: 6.28 | O29: 26 | P29: 16 | Q29: 29 | R29: 35 | S29: 11
A30: General Physics 2 | B30: ='SHS- CONSO'!B82 -> 0 | C30: ='SHS- CONSO'!C82 -> 0 | D30: =SUM(B30:C30) -> 0 | G30: =SUM(E30:F30) -> 0 | I30: ='SHS- CONSO'!I82
A31: TOTAL | B31: =SUM(B18:B30) -> 4119 | C31: =SUM(C18:C30) -> 4116 | D31: =SUM(D18:D30) -> 8235 | E31: =SUM(E18:E30) -> 2690 | F31: =SUM(F18:F30) -> 2695 | G31: =SUM(G18:G30) -> 5385 | I31: =AVERAGE(I18:I30) -> 40 | J31: =IFERROR((AVERAGE(J17:J20,J24:J27,J29:J30)),"") -> 38 | K31: =IFERROR((AVERAGE(K17:K20,K24:K27,K29:K30)),"") -> 7.1666667 | L31: =IFERROR((AVERAGE(L17:L20,L24:L27,L29:L30)),"") -> 22.676667 | M31: =IFERROR((AVERAGE(M17:M20,M24:M27,M29:M30)),"") -> 48.592857 | N31: =IFERROR((AVERAGE(N17:N20,N24:N27,N29:N30)),"") -> 5.3833333 | O31: =IFERROR((AVERAGE(O17:O20,O24:O27,O29:O30)),"") -> 16.666667 | P31: =IFERROR((AVERAGE(P17:P20,P24:P27,P29:P30)),"") -> 14.333333 | Q31: =IFERROR((AVERAGE(Q17:Q20,Q24:Q27,Q29:Q30)),"") -> 21 | ... S31: =IFERROR((AVERAGE(S17:S20,S24:S27,S29:S30)),"") -> 18.833333

Sheet TVL
A4: SCHOOLS DIVISION OF PARANAQUE CITY
A5: PARANAQUE NATIONAL HIGH SCHOOL - MAIN
A6: SENIOR HIGH SCHOOL PROGRAM
A7: ASSESSMENT PERFORMANCE METRICS (MEAN, MPS, SD)
A8: SY 2025-2026
A10: ASSESSMENT | B10: 1ST PERIODIC TEST
A12: TVL
A13: GRADE LEVEL | B13: Enrollment based on LIS | E13: Number of Test Takers | H13: % of Test Takers | I13: Total Test Items | J13: Highest Scores | K13: Lowest Scores | L13: MEAN | M13: MPS | N13: SD | O13: TOP 5 ITEMS WITH THE MOST NUMBER OF INCORRECT RESPONSES
B15: Male | C15: Female | D15: Total | E15: Male | F15: Female | G15: Total
O16: Rank 1 | P16: Rank 2 | Q16: Rank 3 | R16: Rank 4 | S16: Rank 5
A17: APPLIED SUBJECTS
A18: Empowerment Technologies: ICT for Professional Track | B18: ='SHS- CONSO'!B42 -> 861 | C18: ='SHS- CONSO'!C42 -> 718 | D18: =SUM(B18:C18) -> 1579 | E18: 825 | F18: 690 | G18: =SUM(E18:F18) -> 1515 | H18: N/A | I18: 40 | J18: 39 | K18: 6 | L18: 22.53 | M18: =IFERROR(((L18/I18)*100)," ") -> 56.325 | N18: 5.74 | O18: 27 | P18: 17 | Q18: 29 | R18: 23 | S18: 15
A19: SPECIALIZED SUBJECTS
A20: Automotive Servicing 1 | B20: ='SHS- CONSO'!B86 -> 131 | C20: ='SHS- CONSO'!C86 -> 6 | D20: =SUM(B20:C20) -> 137 | E20: 123 | F20: 4 | G20: =SUM(E20:F20) -> 127 | H20: N/A | I20: 40 | J20: 39 | K20: 7 | L20: 23.68 | M20: =IFERROR(((L20/I20)*100)," ") -> 59.2 | N20: 6.36 | O20: 8 | P20: 14 | Q20: 40 | R20: 22 | S20: 23
A21: Automotive Servicing 2 | B21: N/A | C21: N/A | D21: =SUM(B21:C21) -> 0 | G21: =SUM(E21:F21) -> 0 | H21: N/A | I21: ='SHS- CONSO'!I87 -> 40 | M21: =IFERROR(((L21/I21)*100)," ") -> 0
A22: Automotive Servicing 3 | B22: ='SHS- CONSO'!B88 -> 194 | C22: ='SHS- CONSO'!C88 -> 2 | D22: =SUM(B22:C22) -> 196 | E22: 182 | F22: 2 | G22: =SUM(E22:F22) -> 184 | H22: N/A | I22: 40 | J22: 36 | K22: 7 | L22: 23.89 | M22: =IFERROR(((L22/I22)*100)," ") -> 59.725 | N22: 4.86 | O22: 8 | P22: 21 | Q22: 23 | R22: 24 | S22: 35
A23: Automotive Servicing 4 | B23: N/A | C23: N/A | D23: =SUM(B23:C23) -> 0 | G23: =SUM(E23:F23) -> 0 | H23: N/A | I23: ='SHS- CONSO'!I89 -> 40 | M23: =IFERROR(((L23/I23)*100)," ") -> 0
A24: Beauty Care 1 | B24: ='SHS- CONSO'!B92 -> 8 | C24: ='SHS- CONSO'!C92 -> 48 | D24: =SUM(B24:C24) -> 56 | E24: 8 | F24: 38 | G24: =SUM(E24:F24) -> 46 | H24: N/A | I24: 40 | J24: 29 | K24: 10 | L24: 21 | M24: =IFERROR(((L24/I24)*100)," ") -> 52.5 | N24: 4.87 | O24: 5 | P24: 9 | Q24: 20 | R24: 23 | S24: 39
A25: Beauty Care 2 | D25: =SUM(B25:C25) -> 0 | G25: =SUM(E25:F25) -> 0 | H25: N/A | I25: ='SHS- CONSO'!I93 -> 40 | M25: =IFERROR(((L25/I25)*100)," ") -> 0
A26: Beauty Care 3 | B26: ='SHS- CONSO'!B94 -> 8 | C26: ='SHS- CONSO'!C94 -> 66 | D26: =SUM(B26:C26) -> 74 | E26: 7 | F26: 61 | G26: =SUM(E26:F26) -> 68 | H26: N/A | I26: 40 | J26: 28 | K26: 11 | L26: 21.8 | M26: =IFERROR(((L26/I26)*100)," ") -> 54.5 | N26: 3.8 | O26: 9 | P26: 15 | Q26: 30 | R26: 32 | S26: 39
A27: Beauty Care 4 | D27: =SUM(B27:C27) -> 0 | G27: =SUM(E27:F27) -> 0 | H27: N/A | I27: ='SHS- CONSO'!I95 -> 40 | M27: =IFERROR(((L27/I27)*100)," ") -> 0
A28: Cookery 1 | B28: ='SHS- CONSO'!B98 -> 226 | C28: ='SHS- CONSO'!C98 -> 309 | D28: =SUM(B28:C28) -> 535 | E28: 211 | F28: 297 | G28: =SUM(E28:F28) -> 508 | H28: N/A | I28: 40 | J28: 39 | K28: 9 | L28: 18.67 | M28: =IFERROR(((L28/I28)*100)," ") -> 46.675 | N28: 7.17 | O28: 23 | P28: 14 | Q28: 10 | R28: 33 | S28: 40
A29: Cookery 2 | D29: =SUM(B29:C29) -> 0 | G29: =SUM(E29:F29) -> 0 | H29: N/A | I29: ='SHS- CONSO'!I99 -> 40 | M29: =IFERROR(((L29/I29)*100)," ") -> 0
A30: Cookery 3 | B30: ='SHS- CONSO'!B100 -> 188 | C30: ='SHS- CONSO'!C100 -> 266 | D30: =SUM(B30:C30) -> 454 | E30: 178 | F30: 257 | G30: =SUM(E30:F30) -> 435 | H30: N/A | I30: 40 | J30: 36 | K30: 12 | L30: 19.49 | M30: =IFERROR(((L30/I30)*100)," ") -> 48.725 | N30: 8.12 | O30: 11 | P30: 37 | Q30: 4 | R30: 10 | S30: 5
A31: Cookery 4 | D31: =SUM(B31:C31) -> 0 | G31: =SUM(E31:F31) -> 0 | H31: N/A | I31: ='SHS- CONSO'!I101 -> 40 | M31: =IFERROR(((L31/I31)*100)," ") -> 0
A32: Dressmaking 1 | B32: ='SHS- CONSO'!B104 -> 7 | C32: ='SHS- CONSO'!C104 -> 27 | D32: =SUM(B32:C32) -> 34 | E32: 7 | F32: 23 | G32: =SUM(E32:F32) -> 30 | H32: N/A | I32: 40 | J32: 33 | K32: 6 | L32: 18.5 | M32: =IFERROR(((L32/I32)*100)," ") -> 46.25 | N32: 6.8 | O32: 11 | P32: 12 | Q32: 17 | R32: 34 | S32: 35
A33: Dressmaking 2 | D33: =SUM(B33:C33) -> 0 | G33: =SUM(E33:F33) -> 0 | H33: N/A | I33: 40 | M33: =IFERROR(((L33/I33)*100)," ") -> 0
A34: Dressmaking 3 | B34: ='SHS- CONSO'!B106 -> 8 | C34: ='SHS- CONSO'!C106 -> 10 | D34: =SUM(B34:C34) -> 18 | E34: 8 | F34: 10 | G34: =SUM(E34:F34) -> 18 | H34: N/A | I34: 40 | J34: 33 | K34: 11 | L34: 21.8 | M34: =IFERROR(((L34/I34)*100)," ") -> 54.5 | N34: 7.8 | O34: 3 | P34: 19 | Q34: 21 | R34: 4 | S34: 22
A35: Dressmaking 4 | B35: N/A | C35: N/A | D35: =SUM(B35:C35) -> 0 | G35: =SUM(E35:F35) -> 0 | H35: N/A | I35: 40 | M35: =IFERROR(((L35/I35)*100)," ") -> 0
A36: EIM 1 | B36: 53 | C36: 4 | D36: =SUM(B36:C36) -> 57 | E36: 53 | F36: 4 | G36: =SUM(E36:F36) -> 57 | H36: N/A | I36: ='SHS- CONSO'!I108 -> 40 | J36: 32 | K36: 9 | L36: 20.7 | M36: =IFERROR(((L36/I36)*100)," ") -> 51.75 | N36: 7.47 | O36: 39 | P36: 37 | Q36: 21 | R36: 24 | S36: 9
A37: EIM 2 | B37: 0 | C37: 0 | D37: =SUM(B37:C37) -> 0 | G37: =SUM(E37:F37) -> 0 | H37: N/A | I37: 40 | M37: =IFERROR(((L37/I37)*100)," ") -> 0
A38: EIM 3 | B38: 74 | C38: 9 | D38: =SUM(B38:C38) -> 83 | E38: 72 | F38: 5 | G38: =SUM(E38:F38) -> 77 | H38: N/A | I38: ='SHS- CONSO'!I110 -> 40 | J38: 31 | K38: 12 | L38: 19.3 | M38: =IFERROR(((L38/I38)*100)," ") -> 48.25 | N38: 4.69 | O38: 40 | P38: 5 | Q38: 8 | R38: 30 | S38: 25
A39: EIM 4 | B39: N/A | C39: N/A | D39: =SUM(B39:C39) -> 0 | G39: =SUM(E39:F39) -> 0 | H39: N/A | I39: 40 | M39: =IFERROR(((L39/I39)*100)," ") -> 0
A40: EPAS 1 | B40: 51 | C40: 0 | D40: =SUM(B40:C40) -> 51 | E40: 42 | F40: 0 | G40: =SUM(E40:F40) -> 42 | H40: N/A | I40: ='SHS- CONSO'!I112 -> 40 | J40: 23 | K40: 5 | L40: 14.4 | M40: =IFERROR(((L40/I40)*100)," ") -> 36 | N40: 4.1 | O40: 20 | P40: 24 | Q40: 13 | R40: 27 | S40: 10
A41: EPAS 2 | B41: N/A | C41: N/A | D41: =SUM(B41:C41) -> 0 | G41: =SUM(E41:F41) -> 0 | H41: N/A | I41: 40 | M41: =IFERROR(((L41/I41)*100)," ") -> 0
A42: EPAS 3 | B42: 34 | C42: 5 | D42: =SUM(B42:C42) -> 39 | E42: 33 | F42: 4 | G42: =SUM(E42:F42) -> 37 | H42: N/A | I42: ='SHS- CONSO'!I114 -> 40 | J42: 27 | K42: 14 | L42: 19.9 | M42: =IFERROR(((L42/I42)*100)," ") -> 49.75 | N42: 7.47 | O42: 34 | P42: 23 | Q42: 6 | R42: 38 | S42: 33
A43: EPAS 4 | B43: N/A | C43: N/A | D43: =SUM(B43:C43) -> 0 | G43: =SUM(E43:F43) -> 0 | H43: N/A | I43: 40 | M43: =IFERROR(((L43/I43)*100)," ") -> 0
A44: CSS 1 & CSS 2 | B44: ='SHS- CONSO'!B122 -> 239 | C44: ='SHS- CONSO'!C122 -> 80 | D44: =SUM(B44:C44) -> 319 | E44: 237 | F44: 78 | G44: =SUM(E44:F44) -> 315 | H44: N/A | I44: ='SHS- CONSO'!I116 -> 40 | J44: 34 | K44: 8 | L44: 19.53 | M44: =IFERROR(((L44/I44)*100)," ") -> 48.825 | N44: 5.44 | O44: 27 | P44: 32 | Q44: 36 | R44: 19 | S44: 16
A45: CSS 2 | D45: =SUM(B45:C45) -> 0 | G45: =SUM(E45:F45) -> 0 | H45: N/A | I45: 40 | M45: =IFERROR(((L45/I45)*100)," ") -> 0
A46: CSS 5 & CSS 6 | B46: ='SHS- CONSO'!B124 -> 233 | C46: ='SHS- CONSO'!C124 -> 94 | D46: =SUM(B46:C46) -> 327 | E46: 229 | F46: 92 | G46: =SUM(E46:F46) -> 321 | H46: N/A | I46: ='SHS- CONSO'!I118 -> 40 | J46: 37 | K46: 5 | L46: 18.57 | M46: =IFERROR(((L46/I46)*100)," ") -> 46.425 | N46: 7.98 | O46: 3 | P46: 33 | Q46: 26 | R46: 31 | S46: 24 | T46: 24
...

Sheet SHS- CONSO
A4: SCHOOLS DIVISION OF PARANAQUE CITY
A5: PARANAQUE NATIONAL HIGH SCHOOL - MAIN
A6: SENIOR HIGH SCHOOL PROGRAM
A7: ASSESSMENT PERFORMANCE METRICS (MEAN, MPS, SD)
A8: SY 2025-2026
A10: ASSESSMENT | B10: 1ST PERIODIC TEST
A12: CORE SUBJECTS
A13: GRADE LEVEL | B13: Enrollment based on LIS | E13: Number of Test Takers | H13: % of Test Takers | I13: Total Test Items | J13: Highest Scores | K13: Lowest Scores | L13: MEAN | M13: MPS | N13: SD | O13: TOP 5 ITEMS WITH THE MOST NUMBER OF INCORRECT RESPONSES
B15: Male | C15: Female | D15: Total | E15: Male | F15: Female | G15: Total
O16: Rank 1 | P16: Rank 2 | Q16: Rank 3 | R16: Rank 4 | S16: Rank 5
A17: 21st Century Literature from the Philippines and the World | B17: 980 | C17: 926 | D17: =SUM(B17:C17) -> 1906 | E17: =ENG!E18 -> 813 | F17: =ENG!F18 -> 801 | G17: =SUM(E17:F17) -> 1614 | H17: =IFERROR((G17/D17),"") -> 0.84679958 | I17: =ENG!I18 -> 40 | J17: =ENG!J18 -> 38 | K17: =ENG!K18 -> 11 | L17: =ENG!L18 -> 24.5 | M17: =ENG!M18 -> 61.25 | N17: =ENG!N18 -> 4.5 | O17: =ENG!O18 -> 4 | P17: =ENG!P18 -> 11 | ... S17: =ENG!S18 -> 38
A18: Contemporary Philippine Arts from the Region | B18: 861 | C18: 718 | D18: =SUM(B18:C18) -> 1579 | E18: =HumSS!E18 -> 795 | F18: =HumSS!F18 -> 651 | G18: =SUM(E18:F18) -> 1446 | H18: =IFERROR((G18/D18),"") -> 0.91576947 | I18: =HumSS!I18 -> 40 | J18: =HumSS!J18 -> 40 | K18: =HumSS!K18 -> 8 | L18: =HumSS!L18 -> 20.16 | M18: =HumSS!M18 -> 50.4 | N18: =HumSS!N18 -> 20.03 | O18: =HumSS!O18 -> 39 | P18: =HumSS!P18 -> 13 | ... S18: =HumSS!S18 -> 23
A19: Disaster Risk Reduction and Management | B19: 169 | C19: 181 | D19: =SUM(B19:C19) -> 350 | E19: =SCI!E18 -> 170 | F19: =SCI!F18 -> 181 | G19: =SUM(E19:F19) -> 351 | H19: =IFERROR((G19/D19),"") -> 1.0028571 | I19: =SCI!I18 -> 40 | J19: =SCI!J18 -> 40 | K19: =SCI!K18 -> 10 | L19: =SCI!L18 -> 25.24 | M19: =SCI!M18 -> 63.1 | N19: =SCI!N18 -> 4.4 | O19: =SCI!O18 -> 29 | P19: =SCI!P18 -> 6 | ... S19: =SCI!S18 -> 27
A20: Earth Science | B20: 87 | C20: 65 | D20: =SUM(B20:C20) -> 152 | E20: =SCI!E19 -> 587 | F20: =SCI!F19 -> 483 | G20: =SUM(E20:F20) -> 1070 | H20: =IFERROR((G20/D20),"") -> 7.0394737 | I20: =SCI!I20 -> 40 | J20: =SCI!J20 -> 36 | K20: =SCI!K20 -> 7 | L20: =SCI!L20 -> 24.17 | M20: =SCI!M20 -> 60.425 | N20: =SCI!N20 -> 5.02 | O20: =SCI!O20 -> 6 | P20: =SCI!P20 -> 21 | ... S20: =SCI!S20 -> 7
A21: Earth and Life Science | B21: 634 | C21: 556 | D21: =SUM(B21:C21) -> 1190 | E21: =SCI!E19 -> 587 | F21: =SCI!F19 -> 483 | G21: =SUM(E21:F21) -> 1070 | H21: =IFERROR((G21/D21),"") -> 0.89915966 | I21: =SCI!I19 -> 40 | J21: =SCI!J19 -> 33 | K21: =SCI!K19 -> 6 | L21: =SCI!L19 -> 16.32 | M21: =SCI!M19 -> 40.8 | N21: =SCI!N19 -> 4.6 | O21: =SCI!O19 -> 21 | P21: =SCI!P19 -> 13 | ... S21: =SCI!S19 -> 8
A22: General Mathematics | B22: 721 | C22: 621 | D22: =SUM(B22:C22) -> 1342 | E22: =MATH!E18 -> 689 | F22: =MATH!F18 -> 613 | G22: =SUM(E22:F22) -> 1302 | H22: =IFERROR((G22/D22),"") -> 0.97019374 | I22: =MATH!I18 -> 40 | J22: =MATH!J18 -> 31 | K22: =MATH!K18 -> 1 | L22: =MATH!L18 -> 14.23 | M22: =MATH!M18 -> 35.575 | N22: =MATH!N18 -> 4.26 | O22: =MATH!O18 -> 24 | P22: =MATH!P18 -> 8 | ... S22: =MATH!S18 -> 30
A23: Introduction to the Philosophy of the Human Person | B23: 848 | C23: 966 | D23: =SUM(B23:C23) -> 1814 | E23: =HumSS!E19 -> 825 | F23: =HumSS!F19 -> 950 | G23: =SUM(E23:F23) -> 1775 | H23: =IFERROR((G23/D23),"") -> 0.97850055 | I23: =HumSS!I19 -> 40 | J23: =HumSS!J19 -> 40 | K23: =HumSS!K19 -> 7 | L23: =HumSS!L19 -> 27.71 | M23: =HumSS!M19 -> 69.275 | N23: =HumSS!N19 -> 6.85 | O23: =HumSS!O19 -> 34 | P23: =HumSS!P19 -> 28 | ... S23: =HumSS!S19 -> 36
A24: Komunikasyon at Pananaliksik sa Wika at Kulturang Pilipino | B24: 721 | C24: 621 | D24: =SUM(B24:C24) -> 1342 | E24: =FIL!E18 -> 671 | F24: =FIL!F18 -> 547 | G24: =SUM(E24:F24) -> 1218 | H24: =IFERROR((G24/D24),"") -> 0.9076006 | I24: =FIL!I18 -> 40 | J24: =FIL!J18 -> 38 | K24: =FIL!K18 -> 6 | L24: =FIL!L18 -> 24.72 | M24: =FIL!M18 -> 61.8 | N24: =FIL!N18 -> 4.8 | O24: =FIL!O18 -> 17 | P24: =FIL!P18 -> 15 | ... S24: =FIL!S18 -> 14
A25: Media and Information Literacy | B25: 848 | C25: 966 | D25: =SUM(B25:C25) -> 1814 | E25: =ENG!E19 -> 799 | F25: =ENG!F19 -> 963 | G25: =SUM(E25:F25) -> 1762 | H25: =IFERROR((G25/D25),"") -> 0.97133407 | I25: =ENG!I19 -> 40 | J25: =ENG!J19 -> 39 | K25: =ENG!K19 -> 9 | L25: =ENG!L19 -> 26.2 | M25: =ENG!M19 -> 65.5 | N25: =ENG!N19 -> 5.4 | O25: =ENG!O19 -> 23 | P25: =ENG!P19 -> 21 | ... S25: =ENG!S19 -> 15
A26: Oral Communication in Context | B26: 721 | C26: 621 | D26: =SUM(B26:C26) -> 1342 | E26: =ENG!E20 -> 726 | F26: =ENG!F20 -> 562 | G26: =SUM(E26:F26) -> 1288 | H26: =IFERROR((G26/D26),"") -> 0.95976155 | I26: =ENG!I20 -> 40 | J26: =ENG!J20 -> 40 | K26: =ENG!K20 -> 5 | L26: =ENG!L20 -> 21.89 | M26: =ENG!M20 -> 54.725 | N26: =ENG!N20 -> 6.34 | O26: =ENG!O20 -> 22 | P26: =ENG!P20 -> 23 | ... S26: =ENG!S20 -> 25
A27: Pagbasa at Pagsusuri ng Iba't-ibang Teksto Tungo sa Pananaliksik | B27: 769 | C27: 891 | D27: =SUM(B27:C27) -> 1660 | E27: =FIL!E19 -> 768 | F27: =FIL!F19 -> 882 | G27: =SUM(E27:F27) -> 1650 | H27: =IFERROR((G27/D27),"") -> 0.9939759 | I27: =FIL!I19 -> 40 | J27: =FIL!J19 -> 40 | K27: =FIL!K19 -> 8 | L27: =FIL!L19 -> 24.43 | M27: =FIL!M19 -> 61.075 | N27: =FIL!N19 -> 4.91 | O27: =FIL!O19 -> 27 | P27: =FIL!P19 -> 28 | ... S27: =FIL!S19 -> 6
A28: Personal Development | B28: 769 | C28: 891 | D28: =SUM(B28:C28) -> 1660 | E28: =ESP!E18 -> 762 | F28: =ESP!F18 -> 887 | G28: =SUM(E28:F28) -> 1649 | H28: =IFERROR((G28/D28),"") -> 0.99337349 | I28: 40 | J28: =ESP!J18 -> 38 | K28: =ESP!K18 -> 5 | L28: =ESP!L18 -> 29.04 | M28: =ESP!M18 -> 72.6 | N28: =ESP!N18 -> 4.85 | O28: =ESP!O18 -> 7 | P28: =ESP!P18 -> 8 | Q28: =ESP!Q18 -> 38 | ... S28: =ESP!S18 -> 40
A29: Physical Education and Health 1 and 2 | B29: 769 | C29: 891 | D29: =SUM(B29:C29) -> 1660 | E29: =PE!E18 | F29: =PE!F18 | G29: =SUM(E29:F29) -> 0 | H29: =IFERROR((G29/D29),"") -> 0 | I29: =PE!I18 -> 40 | J29: =PE!J18 | K29: =PE!K18 | L29: =PE!L18 | M29: =PE!M18 -> 0 | N29: =PE!N18 | O29: =PE!O18 | P29: =PE!P18 | ... S29: =PE!S18
A30: Physical Education and Health 3 and 4 | B30: 848 | C30: 966 | D30: =SUM(B30:C30) -> 1814 | E30: =PE!E19 | F30: =PE!F19 | G30: =SUM(E30:F30) -> 0 | H30: =IFERROR((G30/D30),"") -> 0 | I30: =PE!I19 -> 40 | J30: =PE!J19 | K30: =PE!K19 | L30: =PE!L19 | M30: =PE!M19 -> 0 | N30: =PE!N19 | O30: =PE!O19 | P30: =PE!P19 | ... S30: =PE!S19
A31: Physical Science | B31: 600 | C31: 710 | D31: =SUM(B31:C31) -> 1310 | E31: =SCI!E21 -> 600 | F31: =SCI!F21 -> 710 | G31: =SUM(E31:F31) -> 1310 | H31: =IFERROR((G31/D31),"") -> 1 | I31: =SCI!I21 -> 40 | J31: =SCI!J21 -> 40 | K31: =SCI!K21 -> 6 | L31: =SCI!L21 -> 20.67 | M31: =SCI!M21 -> 51.675 | N31: =SCI!N21 -> 5.77 | O31: =SCI!O21 -> 32 | P31: =SCI!P21 -> 15 | ... S31: =SCI!S21 -> 25
A32: Reading and Writing Skills | B32: 769 | C32: 891 | D32: =SUM(B32:C32) -> 1660 | E32: =ENG!E21 -> 755 | F32: =ENG!F21 -> 877 | G32: =SUM(E32:F32) -> 1632 | H32: =IFERROR((G32/D32),"") -> 0.98313253 | I32: =ENG!I21 -> 40 | J32: =ENG!J21 -> 38 | K32: =ENG!K21 -> 8 | L32: =ENG!L21 -> 26.94 | M32: =ENG!M21 -> 67.35 | N32: =ENG!N21 -> 8.94 | O32: =ENG!O21 -> 34 | P32: =ENG!P21 -> 21 | ... S32: =ENG!S21 -> 36
A33: Statistics and Probability | B33: 769 | C33: 891 | D33: =SUM(B33:C33) -> 1660 | E33: =MATH!E19 -> 767 | F33: =MATH!F19 -> 888 | G33: =SUM(E33:F33) -> 1655 | H33: =IFERROR((G33/D33),"") -> 0.99698795 | I33: =MATH!I19 -> 40 | J33: =MATH!J19 -> 38 | K33: =MATH!K19 -> 5 | L33: =MATH!L19 -> 19.31 | M33: =MATH!M19 -> 48.275 | N33: =MATH!N19 -> 5.25 | O33: =MATH!O19 -> 12 | P33: =MATH!P19 -> 2 | ... S33: =MATH!S19 -> 8
A34: Understanding Culture Society and Politics | B34: 721 | C34: 621 | D34: =SUM(B34:C34) -> 1342 | E34: =HumSS!E20 -> 712 | F34: =HumSS!F20 -> 578 | G34: =SUM(E34:F34) -> 1290 | H34: =IFERROR((G34/D34),"") -> 0.96125186 | I34: =HumSS!I20 -> 40 | J34: =HumSS!J20 -> 37 | K34: =HumSS!K20 -> 5 | L34: =HumSS!L20 -> 16.47 | M34: =HumSS!M20 -> 41.175 | N34: =HumSS!N20 -> 4.23 | O34: =HumSS!O20 -> 8 | P34: =HumSS!P20 -> 19 | ... S34: =HumSS!S20 -> 21
A35: TOTAL | B35: =SUM(B17:B34) -> 12604 | C35: =SUM(C17:C34) -> 12993 | D35: =SUM(D17:D34) -> 25597 | E35: =SUM(E17:E34) -> 11026 | F35: =SUM(F17:F34) -> 11056 | G35: =SUM(G17:G34) -> 22082 | H35: =IFERROR((AVERAGE(H17:H34)),"") -> 1.1900095 | I35: =IFERROR(AVERAGE(I17:I34)," ") -> 40 | J35: =IFERROR(AVERAGE(J17:J34)," ") -> 37.875 | K35: =IFERROR(AVERAGE(K17:K34)," ") -> 6.6875 | L35: =IFERROR(AVERAGE(L17:L34)," ") -> 22.625 | M35: =IFERROR(AVERAGE(M17:M34)," ") -> 50.277778 | N35: =IFERROR(AVERAGE(N17:N34)," ") -> 6.259375
A37: APPLIED SUBJECTS
A38: GRADE LEVEL | B38: Enrollment based on LIS | E38: Number of Test Takers | H38: % of Test Takers | I38: Total Test Items | J38: Highest Scores | K38: Lowest Scores | L38: MEAN | M38: MPS | N38: SD | O38: TOP 5 ITEMS WITH THE MOST NUMBER OF INCORRECT RESPONSES
B40: Male | C40: Female | D40: Total | E40: Male | F40: Female | G40: Total
O41: Rank 1 | P41: Rank 2 | Q41: Rank 3 | R41: Rank 4 | S41: Rank 5
A42: Empowerment Technologies: ICT for Professional Track | B42: 861 | C42: 718 | D42: =SUM(B42:C42) -> 1579 | E42: =TVL!E18 -> 825 | F42: =TVL!F18 -> 690 | G42: =SUM(E42:F42) -> 1515 | H42: =IFERROR((G42/D42),"") -> 0.95946802 | I42: =TVL!I18 -> 40 | J42: =TVL!J18 -> 39 | K42: =TVL!K18 -> 6 | L42: =TVL!L18 -> 22.53 | M42: =TVL!M18 -> 56.325 | N42: =TVL!N18 -> 5.74 | O42: =TVL!O18 -> 27 | P42: =TVL!P18 -> 17 | ... S42: =TVL!S18 -> 15
A43: English for Academic and Professional Purposes | B43: 721 | C43: 621 | D43: =SUM(B43:C43) -> 1342 | E43: =ENG!E23 -> 674 | F43: =ENG!F23 -> 594 | G43: =SUM(E43:F43) -> 1268 | H43: =IFERROR((G43/D43),"") -> 0.94485842 | I43: =ENG!I23 -> 40 | J43: =ENG!J23 -> 34 | K43: =ENG!K23 -> 13 | L43: =ENG!L23 -> 23.5 | M43: =ENG!M23 -> 58.75 | N43: =ENG!N23 -> 3.5 | O43: =ENG!O23 -> 36 | P43: =ENG!P23 -> 9 | ... S43: =ENG!S23 -> 3
A44: Entrepreneurship | B44: 1709 | C44: 1684 | D44: =SUM(B44:C44) -> 3393 | E44: =ABM!E18 -> 1661 | F44: =ABM!F18 -> 1579 | G44: =SUM(E44:F44) -> 3240 | H44: =IFERROR((G44/D44),"") -> 0.95490716 | I44: 40 | J44: =ABM!J18 -> 39 | K44: =ABM!K18 -> 3 | L44: =ABM!L18 -> 28.96 | M44: =ABM!M18 -> 72.4 | N44: =ABM!N18 -> 6.21 | O44: =ABM!O18 -> 16 | P44: =ABM!P18 -> 24 | Q44: =ABM!Q18 -> 17 | ... S44: =ABM!S18 -> 28
A45: Pagsulat sa Filipino sa Piling Larangan | B45: 848 | C45: 966 | D45: =SUM(B45:C45) -> 1814 | E45: =FIL!E21 -> 730 | F45: =FIL!F21 -> 915 | G45: =SUM(E45:F45) -> 1645 | H45: =IFERROR((G45/D45),"") -> 0.90683572 | I45: =FIL!I21 -> 40 | J45: =FIL!J21 -> 36 | K45: =FIL!K21 -> 10 | L45: =FIL!L21 -> 23.51 | M45: =FIL!M21 -> 58.775 | N45: =FIL!N21 -> 5.53 | O45: =FIL!O21 -> 40 | P45: =FIL!P21 -> 30 | ... S45: =FIL!S21 -> 24
A46: Practical Research 1 | B46: 769 | C46: 891 | D46: =SUM(B46:C46) -> 1660 | E46: =ENG!E25 -> 747 | F46: =ENG!F25 -> 871 | G46: =SUM(E46:F46) -> 1618 | H46: =IFERROR((G46/D46),"") -> 0.9746988 | I46: =ENG!I25 -> 40 | J46: =ENG!J25 -> 40 | K46: =ENG!K25 -> 9 | L46: =ENG!L25 -> 27.56 | M46: =ENG!M25 -> 68.9 | N46: =ENG!N25 -> 6.57 | O46: =ENG!O25 -> 11 | P46: =ENG!P25 -> 2 | ... S46: =ENG!S25 -> 10
A47: Practical Research 2 | B47: 1709 | C47: 1684 | D47: =SUM(B47:C47) -> 3393 | E47: =SUM(ENG!E26,SCI!E23) -> 1585 | F47: =SUM(ENG!F26,SCI!F23) -> 1616 | G47: =SUM(E47:F47) -> 3201 | H47: =IFERROR((G47/D47),"") -> 0.94341291 | I47: 40 | J47: =IFERROR((AVERAGE(ENG!J26,SCI!J23)),"") -> 40 | K47: =IFERROR((AVERAGE(ENG!K26,SCI!K23)),"") -> 8.5 | L47: =IFERROR((AVERAGE(ENG!L26,SCI!L23)),"") -> 27.04 | M47: =IFERROR(((L47/I47)*100)," ") -> 67.6 | N47: =IFERROR((AVERAGE(ENG!N26,SCI!N23)),"") -> 6.265 | O47: =IFERROR((AVERAGE(ENG!O26,SCI!O23)),"") -> 9.5 | P47: =IFERROR((AVERAGE(ENG!P26,SCI!P23)),"") -> 10.5 | Q47: =IFERROR((AVERAGE(ENG!Q26,SCI!Q23)),"") -> 25 | R47: =IFERROR((AVERAGE(ENG!R26,SCI!R23)),"") -> 16.5 | S47: =IFERROR((AVERAGE(ENG!S26,SCI!S23)),"") -> 34
A48: TOTAL | B48: =SUM(B42:B47) -> 6617 | C48: =SUM(C42:C47) -> 6564 | D48: =SUM(D42:D47) -> 13181 | E48: =SUM(E42:E47) -> 6222 | F48: =SUM(F42:F47) -> 6265 | G48: =SUM(G42:G47) -> 12487 | H48: =IFERROR((AVERAGE(H42:H47)),"") -> 0.9473635 | I48: =IFERROR((AVERAGE(I42:I47))," ") -> 40 | J48: =IFERROR((AVERAGE(J42:J47))," ") -> 38 | K48: =IFERROR((AVERAGE(K42:K47))," ") -> 8.25 | L48: =IFERROR((AVERAGE(L42:L47))," ") -> 25.516667 | M48: =IFERROR((AVERAGE(M42:M47))," ") -> 63.791667 | N48: =IFERROR((AVERAGE(N42:N47))," ") -> 5.6358333
...
